<?xml version="1.0" ?>
<robot name="ee">

	<link name="world">
	<inertial>
      <mass value="0"/>
      <inertia ixx="0.2125" ixy="-0.005" ixz="0.0225" iyy="0.205" iyz="0.045" izz="0.0125"/>
      <origin rpy="0 0 0" xyz="0 0 0"/>
    </inertial>
	</link>

  <link name="y_prismatic">
	 <inertial>
      <mass value="0.01"/>
      <inertia ixx="0.2125" ixy="-0.005" ixz="0.0225" iyy="0.205" iyz="0.045" izz="0.0125"/>
      <origin rpy="0 0 0" xyz="0 0 0"/>
    </inertial>
	</link>
	
	<joint name="y_to_world" type="prismatic">
    <parent link="world"/>
    <child link="y_prismatic"/>
    <axis xyz="0 1 0"/>
    <limit effort="0.0" lower="1" upper="-1" velocity="1000.0"/>
    <origin rpy="0 0 0" xyz="0 0 0"/>
  </joint>
		
	<!-- <link name="x_prismatic">
	 <inertial>
      <mass value="0.01"/>
      <inertia ixx="0.2125" ixy="-0.005" ixz="0.0225" iyy="0.205" iyz="0.045" izz="0.0125"/>
      <origin rpy="0 0 0" xyz="0 0 0"/>
    </inertial>
	</link> -->
	
	<!-- <joint name="x_to_y" type="prismatic">
    <parent link="y_prismatic"/>
    <child link="x_prismatic"/>
    <axis xyz="1 0 0"/>
     <limit effort="0.0" lower="1" upper="-1" velocity="1000.0"/>
    <origin rpy="0 0 0" xyz="0 0 0"/>
  </joint> -->

  <!-- <joint name="ee_to_z" type="continuous">
    <parent link="x_prismatic"/>
    <child link="ee_cube"/>
    <axis xyz="0 0 1"/>
    <origin rpy="0 0 0" xyz="0.0 0.0 0.0"/>
  </joint> -->

	<joint name="planer" type="prismatic">
    <parent link="y_prismatic"/>
    <child link="ee_cube"/>
    <axis xyz="1 0 0"/>
     <limit effort="0.0" lower="1" upper="-1" velocity="1000.0"/>
    <origin rpy="0 0 0" xyz="0 0 0"/>
  </joint>

  <link name="ee_cube">
    <contact>
      <lateral_friction value="1.0"/>
      <rolling_friction value="0.0"/>
      <contact_cfm value="0.0"/>
      <contact_erp value="0.0"/>
      <restitution value ="0.0"/>
    </contact>
    <inertial>
      <origin rpy="0 0 0" xyz="0 0 0"/>
       <!-- <mass value="100.0"/> -->
       <mass value="1000.0"/>
       <inertia ixx="1" ixy="0" ixz="0" iyy="1" iyz="0" izz="1"/>
    </inertial>
    <collision>
      <origin rpy="0 0 0" xyz="0 0 0"/>
      <geometry>
	 	    <mesh filename="ee_vhacd.obj" />
      </geometry>
    </collision>
    <visual>
      <origin rpy="0 0 0" xyz="0 0 0"/>
      <geometry>
				<mesh filename="ee.obj" />
      </geometry>
      <material name="red">
        <color rgba="0.5 0.5 0 1"/>
      </material>
    </visual>
  </link>

</robot> 

